[2024-11-20 19:49:43] ERROR    [src.core.data_processor:processar_dados:90] Erro ao processar dados: 'ProcessadorDados' object has no attribute '_calcular_kpis'
Traceback (most recent call last):
  File "/Users/camilo/projetos_vs/bolt_git/src/core/data_processor.py", line 75, in processar_dados
    'kpis': self._calcular_kpis(df),
AttributeError: 'ProcessadorDados' object has no attribute '_calcular_kpis'
[2024-11-20 19:50:27] INFO     [src.core.data_processor:processar_dados:86] Dados processados: 490 registros
